Workbook

Sheet COST_UPS SAVER (Allin)
A3: Pls. Change fuel Surchrage (weekly) | D3: 0.5025
A4: Country / Zone | B4: ZONE 7 | C4: ZONE 8 | D4: ZONE 9 | E4: USA | F4: Canada | G4: Mexico | H4: Germany | I4: Belgium | J4: UK | K4: Denmark | L4: Austria | M4: Norway | N4: Japan | O4: Hong Kong | P4: Australia | Q4: New Zealand | R4: ZONE 1 | S4: ZONE 2 | T4: ZONE 3 | U4: ZONE 4 | V4: ZONE 6 | W4: ZONE 10 | X4: ZONE 11 | Y4: ZONE 12 | Z4: Israel | AA4: zone-13 | AB4: Egypt | AC4: FRENCH GUINEA | AD4: UAE | AE4: China | AF4: zone-14 | AG4: zone-15
G5: Puerto Rico | I5: Netherlands | K5: France | L5: Ireland | M5: Finland | N5: South Korea | O5: Singapore | AE5: Indonesia
B6: REST OF WORLD COUNTRIES | I6: Luxembourg | K6: Italy | L6: Portugal | M6: Greece | O6: Malaysia | AE6: Philipines
K7: Spain | L7: Sweden | O7: Thailand
K8: Switzerland | AI8: Zone Guide
A9: 0.5 | B9: =('COST_UPS SAVER'!B9*'COST_UPS SAVER (Allin)'!$D$3+'COST_UPS SAVER'!B9)*118% -> 2103.6052 | C9: =('COST_UPS SAVER'!C9*'COST_UPS SAVER (Allin)'!$D$3+'COST_UPS SAVER'!C9)*118% -> 2166.8995 | D9: =('COST_UPS SAVER'!D9*'COST_UPS SAVER (Allin)'!$D$3+'COST_UPS SAVER'!D9)*118% -> 2215.301 | E9: =('COST_UPS SAVER'!E9*'COST_UPS SAVER (Allin)'!$D$3+'COST_UPS SAVER'!E9)*118% -> 1919.307 | F9: =('COST_UPS SAVER'!F9*'COST_UPS SAVER (Allin)'!$D$3+'COST_UPS SAVER'!F9)*118% -> 1986.3245 | G9: =('COST_UPS SAVER'!G9*'COST_UPS SAVER (Allin)'!$D$3+'COST_UPS SAVER'!G9)*118% -> 2003.0789 | H9: =('COST_UPS SAVER'!H9*'COST_UPS SAVER (Allin)'!$D$3+'COST_UPS SAVER'!H9)*118% -> 1366.4126 | I9: =('COST_UPS SAVER'!I9*'COST_UPS SAVER (Allin)'!$D$3+'COST_UPS SAVER'!I9)*118% -> 1463.2156 | ... AG9: =('COST_UPS SAVER'!AG9*'COST_UPS SAVER (Allin)'!$D$3+'COST_UPS SAVER'!AG9)*118% -> 4039.6666 | AI9: ZONE 1 | AJ9: Bangladesh, Nepal, Sri Lanka,
A10: 0.5 | B10: =('COST_UPS SAVER'!B10*'COST_UPS SAVER (Allin)'!$D$3+'COST_UPS SAVER'!B10)*118% -> 2611.8213 | C10: =('COST_UPS SAVER'!C10*'COST_UPS SAVER (Allin)'!$D$3+'COST_UPS SAVER'!C10)*118% -> 2686.2852 | D10: =('COST_UPS SAVER'!D10*'COST_UPS SAVER (Allin)'!$D$3+'COST_UPS SAVER'!D10)*118% -> 2743.9947 | E10: =('COST_UPS SAVER'!E10*'COST_UPS SAVER (Allin)'!$D$3+'COST_UPS SAVER'!E10)*118% -> 1930.4766 | F10: =('COST_UPS SAVER'!F10*'COST_UPS SAVER (Allin)'!$D$3+'COST_UPS SAVER'!F10)*118% -> 2025.4181 | G10: =('COST_UPS SAVER'!G10*'COST_UPS SAVER (Allin)'!$D$3+'COST_UPS SAVER'!G10)*118% -> 2042.1725 | H10: =('COST_UPS SAVER'!H10*'COST_UPS SAVER (Allin)'!$D$3+'COST_UPS SAVER'!H10)*118% -> 1621.4514 | I10: =('COST_UPS SAVER'!I10*'COST_UPS SAVER (Allin)'!$D$3+'COST_UPS SAVER'!I10)*118% -> 1736.8705 | ... AG10: =('COST_UPS SAVER'!AG10*'COST_UPS SAVER (Allin)'!$D$3+'COST_UPS SAVER'!AG10)*118% -> 5024.4517 | AI10: ZONE 2 | AJ10: Macau, Taiwan, Vietnam,
A11: 1 | B11: =('COST_UPS SAVER'!B11*'COST_UPS SAVER (Allin)'!$D$3+'COST_UPS SAVER'!B11)*118% -> 2999.0336 | C11: =('COST_UPS SAVER'!C11*'COST_UPS SAVER (Allin)'!$D$3+'COST_UPS SAVER'!C11)*118% -> 3105.1446 | D11: =('COST_UPS SAVER'!D11*'COST_UPS SAVER (Allin)'!$D$3+'COST_UPS SAVER'!D11)*118% -> 3181.4701 | E11: =('COST_UPS SAVER'!E11*'COST_UPS SAVER (Allin)'!$D$3+'COST_UPS SAVER'!E11)*118% -> 2580.1741 | F11: =('COST_UPS SAVER'!F11*'COST_UPS SAVER (Allin)'!$D$3+'COST_UPS SAVER'!F11)*118% -> 2669.5308 | G11: =('COST_UPS SAVER'!G11*'COST_UPS SAVER (Allin)'!$D$3+'COST_UPS SAVER'!G11)*118% -> 2691.87 | H11: =('COST_UPS SAVER'!H11*'COST_UPS SAVER (Allin)'!$D$3+'COST_UPS SAVER'!H11)*118% -> 1941.6462 | I11: =('COST_UPS SAVER'!I11*'COST_UPS SAVER (Allin)'!$D$3+'COST_UPS SAVER'!I11)*118% -> 2077.5428 | ... AG11: =('COST_UPS SAVER'!AG11*'COST_UPS SAVER (Allin)'!$D$3+'COST_UPS SAVER'!AG11)*118% -> 5772.8138 | AI11: ZONE 3 | AJ11: Bahrain, Jordan, Kuwait, Lebanon, Oman, Pakistan, Qatar, Saudi Arabia,
A12: 1.5 | B12: =('COST_UPS SAVER'!B12*'COST_UPS SAVER (Allin)'!$D$3+'COST_UPS SAVER'!B12)*118% -> 3470.0177 | C12: =('COST_UPS SAVER'!C12*'COST_UPS SAVER (Allin)'!$D$3+'COST_UPS SAVER'!C12)*118% -> 3611.4991 | D12: =('COST_UPS SAVER'!D12*'COST_UPS SAVER (Allin)'!$D$3+'COST_UPS SAVER'!D12)*118% -> 3706.4406 | E12: =('COST_UPS SAVER'!E12*'COST_UPS SAVER (Allin)'!$D$3+'COST_UPS SAVER'!E12)*118% -> 3021.3727 | F12: =('COST_UPS SAVER'!F12*'COST_UPS SAVER (Allin)'!$D$3+'COST_UPS SAVER'!F12)*118% -> 3123.7606 | G12: =('COST_UPS SAVER'!G12*'COST_UPS SAVER (Allin)'!$D$3+'COST_UPS SAVER'!G12)*118% -> 3149.823 | H12: =('COST_UPS SAVER'!H12*'COST_UPS SAVER (Allin)'!$D$3+'COST_UPS SAVER'!H12)*118% -> 2313.9657 | I12: =('COST_UPS SAVER'!I12*'COST_UPS SAVER (Allin)'!$D$3+'COST_UPS SAVER'!I12)*118% -> 2470.3399 | ... AG12: =('COST_UPS SAVER'!AG12*'COST_UPS SAVER (Allin)'!$D$3+'COST_UPS SAVER'!AG12)*118% -> 6655.2111 | AI12: ZONE 4 | AJ12: Andorra, San Marino,
A13: 2 | B13: =('COST_UPS SAVER'!B13*'COST_UPS SAVER (Allin)'!$D$3+'COST_UPS SAVER'!B13)*118% -> 3868.3996 | C13: =('COST_UPS SAVER'!C13*'COST_UPS SAVER (Allin)'!$D$3+'COST_UPS SAVER'!C13)*118% -> 4043.3898 | D13: =('COST_UPS SAVER'!D13*'COST_UPS SAVER (Allin)'!$D$3+'COST_UPS SAVER'!D13)*118% -> 4156.9472 | E13: =('COST_UPS SAVER'!E13*'COST_UPS SAVER (Allin)'!$D$3+'COST_UPS SAVER'!E13)*118% -> 3406.7234 | F13: =('COST_UPS SAVER'!F13*'COST_UPS SAVER (Allin)'!$D$3+'COST_UPS SAVER'!F13)*118% -> 3462.5713 | G13: =('COST_UPS SAVER'!G13*'COST_UPS SAVER (Allin)'!$D$3+'COST_UPS SAVER'!G13)*118% -> 3462.5713 | H13: =('COST_UPS SAVER'!H13*'COST_UPS SAVER (Allin)'!$D$3+'COST_UPS SAVER'!H13)*118% -> 2503.8486 | I13: =('COST_UPS SAVER'!I13*'COST_UPS SAVER (Allin)'!$D$3+'COST_UPS SAVER'!I13)*118% -> 2662.0844 | ... AG13: =('COST_UPS SAVER'!AG13*'COST_UPS SAVER (Allin)'!$D$3+'COST_UPS SAVER'!AG13)*118% -> 7425.9124 | AI13: ZONE 5 | AJ13: Country wise
A14: 2.5 | B14: =('COST_UPS SAVER'!B14*'COST_UPS SAVER (Allin)'!$D$3+'COST_UPS SAVER'!B14)*118% -> 4341.2454 | C14: =('COST_UPS SAVER'!C14*'COST_UPS SAVER (Allin)'!$D$3+'COST_UPS SAVER'!C14)*118% -> 4547.8827 | D14: =('COST_UPS SAVER'!D14*'COST_UPS SAVER (Allin)'!$D$3+'COST_UPS SAVER'!D14)*118% -> 4680.0561 | E14: =('COST_UPS SAVER'!E14*'COST_UPS SAVER (Allin)'!$D$3+'COST_UPS SAVER'!E14)*118% -> 4155.0856 | F14: =('COST_UPS SAVER'!F14*'COST_UPS SAVER (Allin)'!$D$3+'COST_UPS SAVER'!F14)*118% -> 4222.1031 | G14: =('COST_UPS SAVER'!G14*'COST_UPS SAVER (Allin)'!$D$3+'COST_UPS SAVER'!G14)*118% -> 4222.1031 | H14: =('COST_UPS SAVER'!H14*'COST_UPS SAVER (Allin)'!$D$3+'COST_UPS SAVER'!H14)*118% -> 2874.3065 | I14: =('COST_UPS SAVER'!I14*'COST_UPS SAVER (Allin)'!$D$3+'COST_UPS SAVER'!I14)*118% -> 3039.9887 | ... AG14: =('COST_UPS SAVER'!AG14*'COST_UPS SAVER (Allin)'!$D$3+'COST_UPS SAVER'!AG14)*118% -> 8308.3096 | AI14: ZONE 6 | AJ14: Guernsey, Jersey, Saipan,
A15: 3 | B15: =('COST_UPS SAVER'!B15*'COST_UPS SAVER (Allin)'!$D$3+'COST_UPS SAVER'!B15)*118% -> 4739.6272 | C15: =('COST_UPS SAVER'!C15*'COST_UPS SAVER (Allin)'!$D$3+'COST_UPS SAVER'!C15)*118% -> 4979.7733 | D15: =('COST_UPS SAVER'!D15*'COST_UPS SAVER (Allin)'!$D$3+'COST_UPS SAVER'!D15)*118% -> 5132.4243 | E15: =('COST_UPS SAVER'!E15*'COST_UPS SAVER (Allin)'!$D$3+'COST_UPS SAVER'!E15)*118% -> 4544.1595 | F15: =('COST_UPS SAVER'!F15*'COST_UPS SAVER (Allin)'!$D$3+'COST_UPS SAVER'!F15)*118% -> 4620.485 | G15: =('COST_UPS SAVER'!G15*'COST_UPS SAVER (Allin)'!$D$3+'COST_UPS SAVER'!G15)*118% -> 4620.485 | H15: =('COST_UPS SAVER'!H15*'COST_UPS SAVER (Allin)'!$D$3+'COST_UPS SAVER'!H15)*118% -> 3118.1758 | I15: =('COST_UPS SAVER'!I15*'COST_UPS SAVER (Allin)'!$D$3+'COST_UPS SAVER'!I15)*118% -> 3298.7508 | ... AG15: =('COST_UPS SAVER'!AG15*'COST_UPS SAVER (Allin)'!$D$3+'COST_UPS SAVER'!AG15)*118% -> 9079.011 | AI15: ZONE 7 | AJ15: Algeria, Benin, Bhutan, Botswana, Brunei, Burkina Faso, Burundi, Cambodia, Central African Rep, Chad, Cook Isl, Ethiopia, ,
A16: 3.5 | B16: =('COST_UPS SAVER'!B16*'COST_UPS SAVER (Allin)'!$D$3+'COST_UPS SAVER'!B16)*118% -> 5212.473 | C16: =('COST_UPS SAVER'!C16*'COST_UPS SAVER (Allin)'!$D$3+'COST_UPS SAVER'!C16)*118% -> 5486.1278 | D16: =('COST_UPS SAVER'!D16*'COST_UPS SAVER (Allin)'!$D$3+'COST_UPS SAVER'!D16)*118% -> 5657.3948 | E16: =('COST_UPS SAVER'!E16*'COST_UPS SAVER (Allin)'!$D$3+'COST_UPS SAVER'!E16)*118% -> 5201.3034 | F16: =('COST_UPS SAVER'!F16*'COST_UPS SAVER (Allin)'!$D$3+'COST_UPS SAVER'!F16)*118% -> 5331.6152 | G16: =('COST_UPS SAVER'!G16*'COST_UPS SAVER (Allin)'!$D$3+'COST_UPS SAVER'!G16)*118% -> 5331.6152 | H16: =('COST_UPS SAVER'!H16*'COST_UPS SAVER (Allin)'!$D$3+'COST_UPS SAVER'!H16)*118% -> 3458.8482 | I16: =('COST_UPS SAVER'!I16*'COST_UPS SAVER (Allin)'!$D$3+'COST_UPS SAVER'!I16)*118% -> 3624.5303 | ... AG16: =('COST_UPS SAVER'!AG16*'COST_UPS SAVER (Allin)'!$D$3+'COST_UPS SAVER'!AG16)*118% -> 9963.2698 | AJ16: French Polynesia, Gabon, Ghana, Guam, Guinea Rep, Guinea-Bissau, Kenya, Kiribati, Laos, Lesotho, Liberia, Madagascar, Malawi,
A17: 4 | B17: =('COST_UPS SAVER'!B17*'COST_UPS SAVER (Allin)'!$D$3+'COST_UPS SAVER'!B17)*118% -> 5608.9933 | C17: =('COST_UPS SAVER'!C17*'COST_UPS SAVER (Allin)'!$D$3+'COST_UPS SAVER'!C17)*118% -> 5918.0185 | D17: =('COST_UPS SAVER'!D17*'COST_UPS SAVER (Allin)'!$D$3+'COST_UPS SAVER'!D17)*118% -> 6106.0398 | E17: =('COST_UPS SAVER'!E17*'COST_UPS SAVER (Allin)'!$D$3+'COST_UPS SAVER'!E17)*118% -> 5724.4123 | F17: =('COST_UPS SAVER'!F17*'COST_UPS SAVER (Allin)'!$D$3+'COST_UPS SAVER'!F17)*118% -> 5774.6754 | G17: =('COST_UPS SAVER'!G17*'COST_UPS SAVER (Allin)'!$D$3+'COST_UPS SAVER'!G17)*118% -> 5823.077 | H17: =('COST_UPS SAVER'!H17*'COST_UPS SAVER (Allin)'!$D$3+'COST_UPS SAVER'!H17)*118% -> 3704.579 | I17: =('COST_UPS SAVER'!I17*'COST_UPS SAVER (Allin)'!$D$3+'COST_UPS SAVER'!I17)*118% -> 3883.2924 | ... AG17: =('COST_UPS SAVER'!AG17*'COST_UPS SAVER (Allin)'!$D$3+'COST_UPS SAVER'!AG17)*118% -> 10732.11 | AJ17: Mali, Marshal Isl, Mauritania, Micronesia, Mongolia, Morocco, Mozambique, Myanmar, Namibia, Nigeria,
A18: 4.5 | B18: =('COST_UPS SAVER'!B18*'COST_UPS SAVER (Allin)'!$D$3+'COST_UPS SAVER'!B18)*118% -> 6079.9774 | C18: =('COST_UPS SAVER'!C18*'COST_UPS SAVER (Allin)'!$D$3+'COST_UPS SAVER'!C18)*118% -> 6422.5114 | D18: =('COST_UPS SAVER'!D18*'COST_UPS SAVER (Allin)'!$D$3+'COST_UPS SAVER'!D18)*118% -> 6629.1487 | E18: =('COST_UPS SAVER'!E18*'COST_UPS SAVER (Allin)'!$D$3+'COST_UPS SAVER'!E18)*118% -> 6297.7843 | F18: =('COST_UPS SAVER'!F18*'COST_UPS SAVER (Allin)'!$D$3+'COST_UPS SAVER'!F18)*118% -> 6351.7707 | G18: =('COST_UPS SAVER'!G18*'COST_UPS SAVER (Allin)'!$D$3+'COST_UPS SAVER'!G18)*118% -> 6405.757 | H18: =('COST_UPS SAVER'!H18*'COST_UPS SAVER (Allin)'!$D$3+'COST_UPS SAVER'!H18)*118% -> 4048.9746 | I18: =('COST_UPS SAVER'!I18*'COST_UPS SAVER (Allin)'!$D$3+'COST_UPS SAVER'!I18)*118% -> 4207.2103 | ... AG18: =('COST_UPS SAVER'!AG18*'COST_UPS SAVER (Allin)'!$D$3+'COST_UPS SAVER'!AG18)*118% -> 11610.784 | AJ18: Palau, Papua New Guinea, Rwanda, Senegal, Soloman Isl, South Africa, Swaziland, Tanzania, Timor Leste, Togo, Tonga, Tunisia, Tuvalu, Uganda, Vanuatu, Wallis & Futuna Isl, Zambia, Zimbabwe
A19: 5 | B19: =('COST_UPS SAVER'!B19*'COST_UPS SAVER (Allin)'!$D$3+'COST_UPS SAVER'!B19)*118% -> 6478.3593 | C19: =('COST_UPS SAVER'!C19*'COST_UPS SAVER (Allin)'!$D$3+'COST_UPS SAVER'!C19)*118% -> 6852.5404 | D19: =('COST_UPS SAVER'!D19*'COST_UPS SAVER (Allin)'!$D$3+'COST_UPS SAVER'!D19)*118% -> 7077.7937 | E19: =('COST_UPS SAVER'!E19*'COST_UPS SAVER (Allin)'!$D$3+'COST_UPS SAVER'!E19)*118% -> 6802.2773 | F19: =('COST_UPS SAVER'!F19*'COST_UPS SAVER (Allin)'!$D$3+'COST_UPS SAVER'!F19)*118% -> 6859.9868 | G19: =('COST_UPS SAVER'!G19*'COST_UPS SAVER (Allin)'!$D$3+'COST_UPS SAVER'!G19)*118% -> 6917.6963 | H19: =('COST_UPS SAVER'!H19*'COST_UPS SAVER (Allin)'!$D$3+'COST_UPS SAVER'!H19)*118% -> 4294.7054 | I19: =('COST_UPS SAVER'!I19*'COST_UPS SAVER (Allin)'!$D$3+'COST_UPS SAVER'!I19)*118% -> 4462.2492 | ... AG19: =('COST_UPS SAVER'!AG19*'COST_UPS SAVER (Allin)'!$D$3+'COST_UPS SAVER'!AG19)*118% -> 12381.485
A20: 5.5 | B20: =('COST_UPS SAVER'!B20*'COST_UPS SAVER (Allin)'!$D$3+'COST_UPS SAVER'!B20)*118% -> 6917.6963 | C20: =('COST_UPS SAVER'!C20*'COST_UPS SAVER (Allin)'!$D$3+'COST_UPS SAVER'!C20)*118% -> 7325.3862 | D20: =('COST_UPS SAVER'!D20*'COST_UPS SAVER (Allin)'!$D$3+'COST_UPS SAVER'!D20)*118% -> 7569.2554 | E20: =('COST_UPS SAVER'!E20*'COST_UPS SAVER (Allin)'!$D$3+'COST_UPS SAVER'!E20)*118% -> 7263.9534 | F20: =('COST_UPS SAVER'!F20*'COST_UPS SAVER (Allin)'!$D$3+'COST_UPS SAVER'!F20)*118% -> 7325.3862 | G20: =('COST_UPS SAVER'!G20*'COST_UPS SAVER (Allin)'!$D$3+'COST_UPS SAVER'!G20)*118% -> 7384.9573 | H20: =('COST_UPS SAVER'!H20*'COST_UPS SAVER (Allin)'!$D$3+'COST_UPS SAVER'!H20)*118% -> 4581.3914 | I20: =('COST_UPS SAVER'!I20*'COST_UPS SAVER (Allin)'!$D$3+'COST_UPS SAVER'!I20)*118% -> 4760.1048 | ... AG20: =('COST_UPS SAVER'!AG20*'COST_UPS SAVER (Allin)'!$D$3+'COST_UPS SAVER'!AG20)*118% -> 13198.726 | AI20: ZONE 8 | AJ20: Czech Rep, Hungary, Poland,
A21: 6 | B21: =('COST_UPS SAVER'!B21*'COST_UPS SAVER (Allin)'!$D$3+'COST_UPS SAVER'!B21)*118% -> 7291.8774 | C21: =('COST_UPS SAVER'!C21*'COST_UPS SAVER (Allin)'!$D$3+'COST_UPS SAVER'!C21)*118% -> 7733.076 | D21: =('COST_UPS SAVER'!D21*'COST_UPS SAVER (Allin)'!$D$3+'COST_UPS SAVER'!D21)*118% -> 7993.6997 | E21: =('COST_UPS SAVER'!E21*'COST_UPS SAVER (Allin)'!$D$3+'COST_UPS SAVER'!E21)*118% -> 7664.1969 | F21: =('COST_UPS SAVER'!F21*'COST_UPS SAVER (Allin)'!$D$3+'COST_UPS SAVER'!F21)*118% -> 7727.4912 | G21: =('COST_UPS SAVER'!G21*'COST_UPS SAVER (Allin)'!$D$3+'COST_UPS SAVER'!G21)*118% -> 7792.6471 | H21: =('COST_UPS SAVER'!H21*'COST_UPS SAVER (Allin)'!$D$3+'COST_UPS SAVER'!H21)*118% -> 4804.7831 | I21: =('COST_UPS SAVER'!I21*'COST_UPS SAVER (Allin)'!$D$3+'COST_UPS SAVER'!I21)*118% -> 4990.9429 | ... AG21: =('COST_UPS SAVER'!AG21*'COST_UPS SAVER (Allin)'!$D$3+'COST_UPS SAVER'!AG21)*118% -> 13924.749 | AI21: ZONE 9 | AJ21: Anguilla, Antigua & Barbados, Barbados, Belize, Bonaire, Brazil, Cayman Isl, Chile, Colombia, Cuba, Dominica, Dominican Rep
A22: 6.5 | B22: =('COST_UPS SAVER'!B22*'COST_UPS SAVER (Allin)'!$D$3+'COST_UPS SAVER'!B22)*118% -> 7753.5536 | C22: =('COST_UPS SAVER'!C22*'COST_UPS SAVER (Allin)'!$D$3+'COST_UPS SAVER'!C22)*118% -> 8226.3994 | D22: =('COST_UPS SAVER'!D22*'COST_UPS SAVER (Allin)'!$D$3+'COST_UPS SAVER'!D22)*118% -> 8507.5006 | E22: =('COST_UPS SAVER'!E22*'COST_UPS SAVER (Allin)'!$D$3+'COST_UPS SAVER'!E22)*118% -> 8140.7659 | F22: =('COST_UPS SAVER'!F22*'COST_UPS SAVER (Allin)'!$D$3+'COST_UPS SAVER'!F22)*118% -> 8207.7834 | G22: =('COST_UPS SAVER'!G22*'COST_UPS SAVER (Allin)'!$D$3+'COST_UPS SAVER'!G22)*118% -> 8276.6625 | H22: =('COST_UPS SAVER'!H22*'COST_UPS SAVER (Allin)'!$D$3+'COST_UPS SAVER'!H22)*118% -> 5093.3308 | I22: =('COST_UPS SAVER'!I22*'COST_UPS SAVER (Allin)'!$D$3+'COST_UPS SAVER'!I22)*118% -> 5288.7985 | ... AG22: =('COST_UPS SAVER'!AG22*'COST_UPS SAVER (Allin)'!$D$3+'COST_UPS SAVER'!AG22)*118% -> 14784.807 | AJ22: , Ecuador, El Salvador, Honduras, Montserrat, Nicaragua, Peru, St Kitts & Nevis, St Vincent & Grenadi
A23: 7 | B23: =('COST_UPS SAVER'!B23*'COST_UPS SAVER (Allin)'!$D$3+'COST_UPS SAVER'!B23)*118% -> 8140.7659 | C23: =('COST_UPS SAVER'!C23*'COST_UPS SAVER (Allin)'!$D$3+'COST_UPS SAVER'!C23)*118% -> 8648.982 | D23: =('COST_UPS SAVER'!D23*'COST_UPS SAVER (Allin)'!$D$3+'COST_UPS SAVER'!D23)*118% -> 8946.8376 | E23: =('COST_UPS SAVER'!E23*'COST_UPS SAVER (Allin)'!$D$3+'COST_UPS SAVER'!E23)*118% -> 8535.4245 | F23: =('COST_UPS SAVER'!F23*'COST_UPS SAVER (Allin)'!$D$3+'COST_UPS SAVER'!F23)*118% -> 8608.0268 | G23: =('COST_UPS SAVER'!G23*'COST_UPS SAVER (Allin)'!$D$3+'COST_UPS SAVER'!G23)*118% -> 8678.7675 | H23: =('COST_UPS SAVER'!H23*'COST_UPS SAVER (Allin)'!$D$3+'COST_UPS SAVER'!H23)*118% -> 5316.7225 | I23: =('COST_UPS SAVER'!I23*'COST_UPS SAVER (Allin)'!$D$3+'COST_UPS SAVER'!I23)*118% -> 5521.4982 | ... AG23: =('COST_UPS SAVER'!AG23*'COST_UPS SAVER (Allin)'!$D$3+'COST_UPS SAVER'!AG23)*118% -> 15536.893 | AJ23: , St Martin, St Mateen, Turks & Caicos Isl, Venezuela,
A24: 7.5 | B24: =('COST_UPS SAVER'!B24*'COST_UPS SAVER (Allin)'!$D$3+'COST_UPS SAVER'!B24)*118% -> 8602.442 | C24: =('COST_UPS SAVER'!C24*'COST_UPS SAVER (Allin)'!$D$3+'COST_UPS SAVER'!C24)*118% -> 9142.3053 | D24: =('COST_UPS SAVER'!D24*'COST_UPS SAVER (Allin)'!$D$3+'COST_UPS SAVER'!D24)*118% -> 9460.6385 | E24: =('COST_UPS SAVER'!E24*'COST_UPS SAVER (Allin)'!$D$3+'COST_UPS SAVER'!E24)*118% -> 9011.9935 | F24: =('COST_UPS SAVER'!F24*'COST_UPS SAVER (Allin)'!$D$3+'COST_UPS SAVER'!F24)*118% -> 9088.319 | G24: =('COST_UPS SAVER'!G24*'COST_UPS SAVER (Allin)'!$D$3+'COST_UPS SAVER'!G24)*118% -> 9162.7829 | H24: =('COST_UPS SAVER'!H24*'COST_UPS SAVER (Allin)'!$D$3+'COST_UPS SAVER'!H24)*118% -> 5607.1317 | I24: =('COST_UPS SAVER'!I24*'COST_UPS SAVER (Allin)'!$D$3+'COST_UPS SAVER'!I24)*118% -> 5821.2154 | ... AG24: =('COST_UPS SAVER'!AG24*'COST_UPS SAVER (Allin)'!$D$3+'COST_UPS SAVER'!AG24)*118% -> 16396.951
A25: 8 | B25: =('COST_UPS SAVER'!B25*'COST_UPS SAVER (Allin)'!$D$3+'COST_UPS SAVER'!B25)*118% -> 8965.4536 | C25: =('COST_UPS SAVER'!C25*'COST_UPS SAVER (Allin)'!$D$3+'COST_UPS SAVER'!C25)*118% -> 9538.8256 | D25: =('COST_UPS SAVER'!D25*'COST_UPS SAVER (Allin)'!$D$3+'COST_UPS SAVER'!D25)*118% -> 9873.9131 | E25: =('COST_UPS SAVER'!E25*'COST_UPS SAVER (Allin)'!$D$3+'COST_UPS SAVER'!E25)*118% -> 9414.0986 | F25: =('COST_UPS SAVER'!F25*'COST_UPS SAVER (Allin)'!$D$3+'COST_UPS SAVER'!F25)*118% -> 9492.2857 | G25: =('COST_UPS SAVER'!G25*'COST_UPS SAVER (Allin)'!$D$3+'COST_UPS SAVER'!G25)*118% -> 9570.4727 | H25: =('COST_UPS SAVER'!H25*'COST_UPS SAVER (Allin)'!$D$3+'COST_UPS SAVER'!H25)*118% -> 5828.6618 | I25: =('COST_UPS SAVER'!I25*'COST_UPS SAVER (Allin)'!$D$3+'COST_UPS SAVER'!I25)*118% -> 6050.1919 | ... AG25: =('COST_UPS SAVER'!AG25*'COST_UPS SAVER (Allin)'!$D$3+'COST_UPS SAVER'!AG25)*118% -> 17098.773 | AI25: ZONE 10 | AJ25: Albania, Armenia, Belarus, Bosnia & Herzegovina, Croatia, Estonia, Georgia, Kosovo, Latvia, Lithuania,
A26: 8.5 | B26: =('COST_UPS SAVER'!B26*'COST_UPS SAVER (Allin)'!$D$3+'COST_UPS SAVER'!B26)*118% -> 9391.7594 | C26: =('COST_UPS SAVER'!C26*'COST_UPS SAVER (Allin)'!$D$3+'COST_UPS SAVER'!C26)*118% -> 9998.6402 | D26: =('COST_UPS SAVER'!D26*'COST_UPS SAVER (Allin)'!$D$3+'COST_UPS SAVER'!D26)*118% -> 10350.482 | E26: =('COST_UPS SAVER'!E26*'COST_UPS SAVER (Allin)'!$D$3+'COST_UPS SAVER'!E26)*118% -> 9883.2211 | F26: =('COST_UPS SAVER'!F26*'COST_UPS SAVER (Allin)'!$D$3+'COST_UPS SAVER'!F26)*118% -> 9965.1314 | G26: =('COST_UPS SAVER'!G26*'COST_UPS SAVER (Allin)'!$D$3+'COST_UPS SAVER'!G26)*118% -> 10047.042 | H26: =('COST_UPS SAVER'!H26*'COST_UPS SAVER (Allin)'!$D$3+'COST_UPS SAVER'!H26)*118% -> 6120.9326 | I26: =('COST_UPS SAVER'!I26*'COST_UPS SAVER (Allin)'!$D$3+'COST_UPS SAVER'!I26)*118% -> 6351.7707 | ... AG26: =('COST_UPS SAVER'!AG26*'COST_UPS SAVER (Allin)'!$D$3+'COST_UPS SAVER'!AG26)*118% -> 17893.675 | AJ26: Macedonia, Moldova, Montenegro, Serbia Montenegro, Slovenia, Ukraine,
A27: 9 | B27: =('COST_UPS SAVER'!B27*'COST_UPS SAVER (Allin)'!$D$3+'COST_UPS SAVER'!B27)*118% -> 9734.2933 | C27: =('COST_UPS SAVER'!C27*'COST_UPS SAVER (Allin)'!$D$3+'COST_UPS SAVER'!C27)*118% -> 10372.821 | D27: =('COST_UPS SAVER'!D27*'COST_UPS SAVER (Allin)'!$D$3+'COST_UPS SAVER'!D27)*118% -> 10743.279 | E27: =('COST_UPS SAVER'!E27*'COST_UPS SAVER (Allin)'!$D$3+'COST_UPS SAVER'!E27)*118% -> 10279.741 | F27: =('COST_UPS SAVER'!F27*'COST_UPS SAVER (Allin)'!$D$3+'COST_UPS SAVER'!F27)*118% -> 10365.375 | G27: =('COST_UPS SAVER'!G27*'COST_UPS SAVER (Allin)'!$D$3+'COST_UPS SAVER'!G27)*118% -> 10449.147 | H27: =('COST_UPS SAVER'!H27*'COST_UPS SAVER (Allin)'!$D$3+'COST_UPS SAVER'!H27)*118% -> 6340.6011 | I27: =('COST_UPS SAVER'!I27*'COST_UPS SAVER (Allin)'!$D$3+'COST_UPS SAVER'!I27)*118% -> 6580.7472 | ... AG27: =('COST_UPS SAVER'!AG27*'COST_UPS SAVER (Allin)'!$D$3+'COST_UPS SAVER'!AG27)*118% -> 18556.404
A28: 9.5 | B28: =('COST_UPS SAVER'!B28*'COST_UPS SAVER (Allin)'!$D$3+'COST_UPS SAVER'!B28)*118% -> 10149.43 | C28: =('COST_UPS SAVER'!C28*'COST_UPS SAVER (Allin)'!$D$3+'COST_UPS SAVER'!C28)*118% -> 10819.605 | D28: =('COST_UPS SAVER'!D28*'COST_UPS SAVER (Allin)'!$D$3+'COST_UPS SAVER'!D28)*118% -> 11208.679 | E28: =('COST_UPS SAVER'!E28*'COST_UPS SAVER (Allin)'!$D$3+'COST_UPS SAVER'!E28)*118% -> 10733.971 | F28: =('COST_UPS SAVER'!F28*'COST_UPS SAVER (Allin)'!$D$3+'COST_UPS SAVER'!F28)*118% -> 10821.466 | G28: =('COST_UPS SAVER'!G28*'COST_UPS SAVER (Allin)'!$D$3+'COST_UPS SAVER'!G28)*118% -> 10910.823 | H28: =('COST_UPS SAVER'!H28*'COST_UPS SAVER (Allin)'!$D$3+'COST_UPS SAVER'!H28)*118% -> 6627.2871 | I28: =('COST_UPS SAVER'!I28*'COST_UPS SAVER (Allin)'!$D$3+'COST_UPS SAVER'!I28)*118% -> 6874.8796 | ... AG28: =('COST_UPS SAVER'!AG28*'COST_UPS SAVER (Allin)'!$D$3+'COST_UPS SAVER'!AG28)*118% -> 19327.105 | AI28: ZONE 11 | AJ28: Maldives, Mauritius, New Caledonia,
A29: 10 | B29: =('COST_UPS SAVER'!B29*'COST_UPS SAVER (Allin)'!$D$3+'COST_UPS SAVER'!B29)*118% -> 10490.102 | C29: =('COST_UPS SAVER'!C29*'COST_UPS SAVER (Allin)'!$D$3+'COST_UPS SAVER'!C29)*118% -> 11193.786 | D29: =('COST_UPS SAVER'!D29*'COST_UPS SAVER (Allin)'!$D$3+'COST_UPS SAVER'!D29)*118% -> 11597.752 | E29: =('COST_UPS SAVER'!E29*'COST_UPS SAVER (Allin)'!$D$3+'COST_UPS SAVER'!E29)*118% -> 11096.983 | F29: =('COST_UPS SAVER'!F29*'COST_UPS SAVER (Allin)'!$D$3+'COST_UPS SAVER'!F29)*118% -> 11188.201 | G29: =('COST_UPS SAVER'!G29*'COST_UPS SAVER (Allin)'!$D$3+'COST_UPS SAVER'!G29)*118% -> 11279.419 | H29: =('COST_UPS SAVER'!H29*'COST_UPS SAVER (Allin)'!$D$3+'COST_UPS SAVER'!H29)*118% -> 6858.1252 | I29: =('COST_UPS SAVER'!I29*'COST_UPS SAVER (Allin)'!$D$3+'COST_UPS SAVER'!I29)*118% -> 7116.8872 | ... AG29: =('COST_UPS SAVER'!AG29*'COST_UPS SAVER (Allin)'!$D$3+'COST_UPS SAVER'!AG29)*118% -> 19986.111
A30: 10.5 | B30: =('COST_UPS SAVER'!B30*'COST_UPS SAVER (Allin)'!$D$3+'COST_UPS SAVER'!B30)*118% -> 10882.899 | C30: =('COST_UPS SAVER'!C30*'COST_UPS SAVER (Allin)'!$D$3+'COST_UPS SAVER'!C30)*118% -> 11618.23 | D30: =('COST_UPS SAVER'!D30*'COST_UPS SAVER (Allin)'!$D$3+'COST_UPS SAVER'!D30)*118% -> 12040.813 | E30: =('COST_UPS SAVER'!E30*'COST_UPS SAVER (Allin)'!$D$3+'COST_UPS SAVER'!E30)*118% -> 10923.854 | F30: =('COST_UPS SAVER'!F30*'COST_UPS SAVER (Allin)'!$D$3+'COST_UPS SAVER'!F30)*118% -> 11013.211 | G30: =('COST_UPS SAVER'!G30*'COST_UPS SAVER (Allin)'!$D$3+'COST_UPS SAVER'!G30)*118% -> 11102.567 | H30: =('COST_UPS SAVER'!H30*'COST_UPS SAVER (Allin)'!$D$3+'COST_UPS SAVER'!H30)*118% -> 7206.2439 | I30: =('COST_UPS SAVER'!I30*'COST_UPS SAVER (Allin)'!$D$3+'COST_UPS SAVER'!I30)*118% -> 7476.1756 | ... AG30: =('COST_UPS SAVER'!AG30*'COST_UPS SAVER (Allin)'!$D$3+'COST_UPS SAVER'!AG30)*118% -> 20715.857 | AI30: ZONE 12 | AJ30: Argentina, Aruba, Bahamas, Bermuda, Bolivia, British Virgin Isl, Costa Rica, Curacao, Grenada, Guadeloupe
A31: 11 | B31: =('COST_UPS SAVER'!B31*'COST_UPS SAVER (Allin)'!$D$3+'COST_UPS SAVER'!B31)*118% -> 11201.232 | C31: =('COST_UPS SAVER'!C31*'COST_UPS SAVER (Allin)'!$D$3+'COST_UPS SAVER'!C31)*118% -> 11968.21 | D31: =('COST_UPS SAVER'!D31*'COST_UPS SAVER (Allin)'!$D$3+'COST_UPS SAVER'!D31)*118% -> 12407.547 | E31: =('COST_UPS SAVER'!E31*'COST_UPS SAVER (Allin)'!$D$3+'COST_UPS SAVER'!E31)*118% -> 11305.482 | F31: =('COST_UPS SAVER'!F31*'COST_UPS SAVER (Allin)'!$D$3+'COST_UPS SAVER'!F31)*118% -> 11396.7 | G31: =('COST_UPS SAVER'!G31*'COST_UPS SAVER (Allin)'!$D$3+'COST_UPS SAVER'!G31)*118% -> 11487.918 | H31: =('COST_UPS SAVER'!H31*'COST_UPS SAVER (Allin)'!$D$3+'COST_UPS SAVER'!H31)*118% -> 7491.0683 | I31: =('COST_UPS SAVER'!I31*'COST_UPS SAVER (Allin)'!$D$3+'COST_UPS SAVER'!I31)*118% -> 7772.1696 | ... AG31: =('COST_UPS SAVER'!AG31*'COST_UPS SAVER (Allin)'!$D$3+'COST_UPS SAVER'!AG31)*118% -> 21332.046 | AJ31: Guatemala, Guyana, Haiti, Jamaica, Martinique, Panama, Paraguay, St Barthelemy, St Lucia, Suriname, Trinidad & Tobago, US Virgin Isl, Uruguay,
A32: 11.5 | B32: =('COST_UPS SAVER'!B32*'COST_UPS SAVER (Allin)'!$D$3+'COST_UPS SAVER'!B32)*118% -> 11592.168 | C32: =('COST_UPS SAVER'!C32*'COST_UPS SAVER (Allin)'!$D$3+'COST_UPS SAVER'!C32)*118% -> 12392.655 | D32: =('COST_UPS SAVER'!D32*'COST_UPS SAVER (Allin)'!$D$3+'COST_UPS SAVER'!D32)*118% -> 12848.746 | E32: =('COST_UPS SAVER'!E32*'COST_UPS SAVER (Allin)'!$D$3+'COST_UPS SAVER'!E32)*118% -> 11759.711 | F32: =('COST_UPS SAVER'!F32*'COST_UPS SAVER (Allin)'!$D$3+'COST_UPS SAVER'!F32)*118% -> 11856.514 | G32: =('COST_UPS SAVER'!G32*'COST_UPS SAVER (Allin)'!$D$3+'COST_UPS SAVER'!G32)*118% -> 11951.456 | H32: =('COST_UPS SAVER'!H32*'COST_UPS SAVER (Allin)'!$D$3+'COST_UPS SAVER'!H32)*118% -> 7826.1559 | I32: =('COST_UPS SAVER'!I32*'COST_UPS SAVER (Allin)'!$D$3+'COST_UPS SAVER'!I32)*118% -> 8118.4267 | ... AG32: =('COST_UPS SAVER'!AG32*'COST_UPS SAVER (Allin)'!$D$3+'COST_UPS SAVER'!AG32)*118% -> 22058.069
A33: 12 | B33: =('COST_UPS SAVER'!B33*'COST_UPS SAVER (Allin)'!$D$3+'COST_UPS SAVER'!B33)*118% -> 11912.362 | C33: =('COST_UPS SAVER'!C33*'COST_UPS SAVER (Allin)'!$D$3+'COST_UPS SAVER'!C33)*118% -> 12742.635 | D33: =('COST_UPS SAVER'!D33*'COST_UPS SAVER (Allin)'!$D$3+'COST_UPS SAVER'!D33)*118% -> 13217.342 | E33: =('COST_UPS SAVER'!E33*'COST_UPS SAVER (Allin)'!$D$3+'COST_UPS SAVER'!E33)*118% -> 12132.031 | F33: =('COST_UPS SAVER'!F33*'COST_UPS SAVER (Allin)'!$D$3+'COST_UPS SAVER'!F33)*118% -> 12230.696 | G33: =('COST_UPS SAVER'!G33*'COST_UPS SAVER (Allin)'!$D$3+'COST_UPS SAVER'!G33)*118% -> 12329.36 | H33: =('COST_UPS SAVER'!H33*'COST_UPS SAVER (Allin)'!$D$3+'COST_UPS SAVER'!H33)*118% -> 8112.8419 | I33: =('COST_UPS SAVER'!I33*'COST_UPS SAVER (Allin)'!$D$3+'COST_UPS SAVER'!I33)*118% -> 8418.1439 | ... AG33: =('COST_UPS SAVER'!AG33*'COST_UPS SAVER (Allin)'!$D$3+'COST_UPS SAVER'!AG33)*118% -> 22676.119 | AI33: ZONE 13 | AJ33: Bulgaria, Cyprus, Gibraltar, Iceland, Malta, Romania, Slovakia, Turkey,
A34: 12.5 | B34: =('COST_UPS SAVER'!B34*'COST_UPS SAVER (Allin)'!$D$3+'COST_UPS SAVER'!B34)*118% -> 12305.159 | C34: =('COST_UPS SAVER'!C34*'COST_UPS SAVER (Allin)'!$D$3+'COST_UPS SAVER'!C34)*118% -> 13167.079 | D34: =('COST_UPS SAVER'!D34*'COST_UPS SAVER (Allin)'!$D$3+'COST_UPS SAVER'!D34)*118% -> 13658.541 | E34: =('COST_UPS SAVER'!E34*'COST_UPS SAVER (Allin)'!$D$3+'COST_UPS SAVER'!E34)*118% -> 12591.845 | F34: =('COST_UPS SAVER'!F34*'COST_UPS SAVER (Allin)'!$D$3+'COST_UPS SAVER'!F34)*118% -> 12694.233 | G34: =('COST_UPS SAVER'!G34*'COST_UPS SAVER (Allin)'!$D$3+'COST_UPS SAVER'!G34)*118% -> 12794.76 | H34: =('COST_UPS SAVER'!H34*'COST_UPS SAVER (Allin)'!$D$3+'COST_UPS SAVER'!H34)*118% -> 8462.8222 | I34: =('COST_UPS SAVER'!I34*'COST_UPS SAVER (Allin)'!$D$3+'COST_UPS SAVER'!I34)*118% -> 8779.2938 | ... AG34: =('COST_UPS SAVER'!AG34*'COST_UPS SAVER (Allin)'!$D$3+'COST_UPS SAVER'!AG34)*118% -> 23404.004 | AI34: ZONE 14 | AJ34: Angola, Azerbaijan, Cape Verde, Comoros, Equatorial Guinea, Eritrea, Faroe Isl, Greenland, Kazakhstan, Kyrgyzstan, Mayotte, Tajikistan, Uzbekistan,
A35: 13 | B35: =('COST_UPS SAVER'!B35*'COST_UPS SAVER (Allin)'!$D$3+'COST_UPS SAVER'!B35)*118% -> 12621.631 | C35: =('COST_UPS SAVER'!C35*'COST_UPS SAVER (Allin)'!$D$3+'COST_UPS SAVER'!C35)*118% -> 13517.059 | D35: =('COST_UPS SAVER'!D35*'COST_UPS SAVER (Allin)'!$D$3+'COST_UPS SAVER'!D35)*118% -> 14025.276 | E35: =('COST_UPS SAVER'!E35*'COST_UPS SAVER (Allin)'!$D$3+'COST_UPS SAVER'!E35)*118% -> 12941.826 | F35: =('COST_UPS SAVER'!F35*'COST_UPS SAVER (Allin)'!$D$3+'COST_UPS SAVER'!F35)*118% -> 13046.075 | G35: =('COST_UPS SAVER'!G35*'COST_UPS SAVER (Allin)'!$D$3+'COST_UPS SAVER'!G35)*118% -> 13152.186 | H35: =('COST_UPS SAVER'!H35*'COST_UPS SAVER (Allin)'!$D$3+'COST_UPS SAVER'!H35)*118% -> 8747.6467 | I35: =('COST_UPS SAVER'!I35*'COST_UPS SAVER (Allin)'!$D$3+'COST_UPS SAVER'!I35)*118% -> 9075.2878 | ... AG35: =('COST_UPS SAVER'!AG35*'COST_UPS SAVER (Allin)'!$D$3+'COST_UPS SAVER'!AG35)*118% -> 24018.331 | AI35: ZONE 15 | AJ35: American Samoa, Cameroon, Congo, Djibouti, Gambia, Ivory Coast, Niger, Reunion Isl, Seychelles, Sierra Leone, Samoa,
A36: 13.5 | B36: =('COST_UPS SAVER'!B36*'COST_UPS SAVER (Allin)'!$D$3+'COST_UPS SAVER'!B36)*118% -> 13014.428 | C36: =('COST_UPS SAVER'!C36*'COST_UPS SAVER (Allin)'!$D$3+'COST_UPS SAVER'!C36)*118% -> 13941.504 | D36: =('COST_UPS SAVER'!D36*'COST_UPS SAVER (Allin)'!$D$3+'COST_UPS SAVER'!D36)*118% -> 14466.474 | E36: =('COST_UPS SAVER'!E36*'COST_UPS SAVER (Allin)'!$D$3+'COST_UPS SAVER'!E36)*118% -> 13366.27 | F36: =('COST_UPS SAVER'!F36*'COST_UPS SAVER (Allin)'!$D$3+'COST_UPS SAVER'!F36)*118% -> 13474.243 | G36: =('COST_UPS SAVER'!G36*'COST_UPS SAVER (Allin)'!$D$3+'COST_UPS SAVER'!G36)*118% -> 13582.215 | H36: =('COST_UPS SAVER'!H36*'COST_UPS SAVER (Allin)'!$D$3+'COST_UPS SAVER'!H36)*118% -> 9092.0422 | I36: =('COST_UPS SAVER'!I36*'COST_UPS SAVER (Allin)'!$D$3+'COST_UPS SAVER'!I36)*118% -> 9430.8529 | ... AG36: =('COST_UPS SAVER'!AG36*'COST_UPS SAVER (Allin)'!$D$3+'COST_UPS SAVER'!AG36)*118% -> 24746.216 | AJ36: St Croix, St Eustatius, St John, St Kitts & Nevis, St Martin, St Marteen, St Thomas, St Vincent & Grenadi, Tahiti, Tortola, Truk,
A37: 14 | B37: =('COST_UPS SAVER'!B37*'COST_UPS SAVER (Allin)'!$D$3+'COST_UPS SAVER'!B37)*118% -> 13332.761 | C37: =('COST_UPS SAVER'!C37*'COST_UPS SAVER (Allin)'!$D$3+'COST_UPS SAVER'!C37)*118% -> 14291.484 | D37: =('COST_UPS SAVER'!D37*'COST_UPS SAVER (Allin)'!$D$3+'COST_UPS SAVER'!D37)*118% -> 14835.07 | E37: =('COST_UPS SAVER'!E37*'COST_UPS SAVER (Allin)'!$D$3+'COST_UPS SAVER'!E37)*118% -> 13719.974 | F37: =('COST_UPS SAVER'!F37*'COST_UPS SAVER (Allin)'!$D$3+'COST_UPS SAVER'!F37)*118% -> 13831.669 | G37: =('COST_UPS SAVER'!G37*'COST_UPS SAVER (Allin)'!$D$3+'COST_UPS SAVER'!G37)*118% -> 13941.504 | H37: =('COST_UPS SAVER'!H37*'COST_UPS SAVER (Allin)'!$D$3+'COST_UPS SAVER'!H37)*118% -> 9371.2818 | I37: =('COST_UPS SAVER'!I37*'COST_UPS SAVER (Allin)'!$D$3+'COST_UPS SAVER'!I37)*118% -> 9723.1237 | ... AG37: =('COST_UPS SAVER'!AG37*'COST_UPS SAVER (Allin)'!$D$3+'COST_UPS SAVER'!AG37)*118% -> 25362.404 | AJ37: Turks & Caicas Island, Venezuela, Yap, Zaire
A38: 14.5 | B38: =('COST_UPS SAVER'!B38*'COST_UPS SAVER (Allin)'!$D$3+'COST_UPS SAVER'!B38)*118% -> 13723.697 | C38: =('COST_UPS SAVER'!C38*'COST_UPS SAVER (Allin)'!$D$3+'COST_UPS SAVER'!C38)*118% -> 14715.928 | D38: =('COST_UPS SAVER'!D38*'COST_UPS SAVER (Allin)'!$D$3+'COST_UPS SAVER'!D38)*118% -> 15276.269 | E38: =('COST_UPS SAVER'!E38*'COST_UPS SAVER (Allin)'!$D$3+'COST_UPS SAVER'!E38)*118% -> 14146.279 | F38: =('COST_UPS SAVER'!F38*'COST_UPS SAVER (Allin)'!$D$3+'COST_UPS SAVER'!F38)*118% -> 14259.837 | G38: =('COST_UPS SAVER'!G38*'COST_UPS SAVER (Allin)'!$D$3+'COST_UPS SAVER'!G38)*118% -> 14375.256 | H38: =('COST_UPS SAVER'!H38*'COST_UPS SAVER (Allin)'!$D$3+'COST_UPS SAVER'!H38)*118% -> 9715.6774 | I38: =('COST_UPS SAVER'!I38*'COST_UPS SAVER (Allin)'!$D$3+'COST_UPS SAVER'!I38)*118% -> 10078.689 | ... AG38: =('COST_UPS SAVER'!AG38*'COST_UPS SAVER (Allin)'!$D$3+'COST_UPS SAVER'!AG38)*118% -> 26088.427
A39: 15 | B39: =('COST_UPS SAVER'!B39*'COST_UPS SAVER (Allin)'!$D$3+'COST_UPS SAVER'!B39)*118% -> 14043.892 | C39: =('COST_UPS SAVER'!C39*'COST_UPS SAVER (Allin)'!$D$3+'COST_UPS SAVER'!C39)*118% -> 15067.77 | D39: =('COST_UPS SAVER'!D39*'COST_UPS SAVER (Allin)'!$D$3+'COST_UPS SAVER'!D39)*118% -> 15644.865 | E39: =('COST_UPS SAVER'!E39*'COST_UPS SAVER (Allin)'!$D$3+'COST_UPS SAVER'!E39)*118% -> 14513.014 | F39: =('COST_UPS SAVER'!F39*'COST_UPS SAVER (Allin)'!$D$3+'COST_UPS SAVER'!F39)*118% -> 14630.295 | G39: =('COST_UPS SAVER'!G39*'COST_UPS SAVER (Allin)'!$D$3+'COST_UPS SAVER'!G39)*118% -> 14747.575 | H39: =('COST_UPS SAVER'!H39*'COST_UPS SAVER (Allin)'!$D$3+'COST_UPS SAVER'!H39)*118% -> 9994.917 | I39: =('COST_UPS SAVER'!I39*'COST_UPS SAVER (Allin)'!$D$3+'COST_UPS SAVER'!I39)*118% -> 10369.098 | ... AG39: =('COST_UPS SAVER'!AG39*'COST_UPS SAVER (Allin)'!$D$3+'COST_UPS SAVER'!AG39)*118% -> 26708.339
A40: 15.5 | B40: =('COST_UPS SAVER'!B40*'COST_UPS SAVER (Allin)'!$D$3+'COST_UPS SAVER'!B40)*118% -> 14434.827 | C40: =('COST_UPS SAVER'!C40*'COST_UPS SAVER (Allin)'!$D$3+'COST_UPS SAVER'!C40)*118% -> 15490.353 | D40: =('COST_UPS SAVER'!D40*'COST_UPS SAVER (Allin)'!$D$3+'COST_UPS SAVER'!D40)*118% -> 16084.202 | E40: =('COST_UPS SAVER'!E40*'COST_UPS SAVER (Allin)'!$D$3+'COST_UPS SAVER'!E40)*118% -> 16255.469 | F40: =('COST_UPS SAVER'!F40*'COST_UPS SAVER (Allin)'!$D$3+'COST_UPS SAVER'!F40)*118% -> 16387.643 | G40: =('COST_UPS SAVER'!G40*'COST_UPS SAVER (Allin)'!$D$3+'COST_UPS SAVER'!G40)*118% -> 16519.816 | H40: =('COST_UPS SAVER'!H40*'COST_UPS SAVER (Allin)'!$D$3+'COST_UPS SAVER'!H40)*118% -> 11031.827 | I40: =('COST_UPS SAVER'!I40*'COST_UPS SAVER (Allin)'!$D$3+'COST_UPS SAVER'!I40)*118% -> 11718.756 | ... AG40: =('COST_UPS SAVER'!AG40*'COST_UPS SAVER (Allin)'!$D$3+'COST_UPS SAVER'!AG40)*118% -> 27432.501
A41: 16 | B41: =('COST_UPS SAVER'!B41*'COST_UPS SAVER (Allin)'!$D$3+'COST_UPS SAVER'!B41)*118% -> 14753.16 | C41: =('COST_UPS SAVER'!C41*'COST_UPS SAVER (Allin)'!$D$3+'COST_UPS SAVER'!C41)*118% -> 15840.333 | D41: =('COST_UPS SAVER'!D41*'COST_UPS SAVER (Allin)'!$D$3+'COST_UPS SAVER'!D41)*118% -> 16452.799 | E41: =('COST_UPS SAVER'!E41*'COST_UPS SAVER (Allin)'!$D$3+'COST_UPS SAVER'!E41)*118% -> 16598.003 | F41: =('COST_UPS SAVER'!F41*'COST_UPS SAVER (Allin)'!$D$3+'COST_UPS SAVER'!F41)*118% -> 16733.9 | G41: =('COST_UPS SAVER'!G41*'COST_UPS SAVER (Allin)'!$D$3+'COST_UPS SAVER'!G41)*118% -> 16869.797 | H41: =('COST_UPS SAVER'!H41*'COST_UPS SAVER (Allin)'!$D$3+'COST_UPS SAVER'!H41)*118% -> 11325.959 | I41: =('COST_UPS SAVER'!I41*'COST_UPS SAVER (Allin)'!$D$3+'COST_UPS SAVER'!I41)*118% -> 12033.366 | ... AG41: =('COST_UPS SAVER'!AG41*'COST_UPS SAVER (Allin)'!$D$3+'COST_UPS SAVER'!AG41)*118% -> 28048.69
A42: 16.5 | B42: =('COST_UPS SAVER'!B42*'COST_UPS SAVER (Allin)'!$D$3+'COST_UPS SAVER'!B42)*118% -> 15147.819 | C42: =('COST_UPS SAVER'!C42*'COST_UPS SAVER (Allin)'!$D$3+'COST_UPS SAVER'!C42)*118% -> 16266.639 | D42: =('COST_UPS SAVER'!D42*'COST_UPS SAVER (Allin)'!$D$3+'COST_UPS SAVER'!D42)*118% -> 16895.859 | E42: =('COST_UPS SAVER'!E42*'COST_UPS SAVER (Allin)'!$D$3+'COST_UPS SAVER'!E42)*118% -> 17028.032 | F42: =('COST_UPS SAVER'!F42*'COST_UPS SAVER (Allin)'!$D$3+'COST_UPS SAVER'!F42)*118% -> 17165.791 | G42: =('COST_UPS SAVER'!G42*'COST_UPS SAVER (Allin)'!$D$3+'COST_UPS SAVER'!G42)*118% -> 17305.41 | H42: =('COST_UPS SAVER'!H42*'COST_UPS SAVER (Allin)'!$D$3+'COST_UPS SAVER'!H42)*118% -> 11692.694 | I42: =('COST_UPS SAVER'!I42*'COST_UPS SAVER (Allin)'!$D$3+'COST_UPS SAVER'!I42)*118% -> 12418.717 | ... AG42: =('COST_UPS SAVER'!AG42*'COST_UPS SAVER (Allin)'!$D$3+'COST_UPS SAVER'!AG42)*118% -> 28780.297
...

Sheet COST_UPS SAVER
A3: COST Excluding FSC & GST
A4: Country / Zone | B4: ZONE 7 | C4: ZONE 8 | D4: ZONE 9 | E4: USA | F4: Canada | G4: Mexico | H4: Germany | I4: Belgium | J4: UK | K4: Denmark | L4: Austria | M4: Norway | N4: Japan | O4: Hong Kong | P4: Australia | Q4: New Zealand | R4: ZONE 1 | S4: ZONE 2 | T4: ZONE 3 | U4: ZONE 4 | V4: ZONE 6 | W4: ZONE 10 | X4: ZONE 11 | Y4: ZONE 12 | Z4: Israel | AA4: zone-13 | AB4: Egypt | AC4: FRENCH GUINEA | AD4: UAE | AE4: China | AF4: zone-14 | AG4: zone-15
G5: Puerto Rico | I5: Netherlands | K5: France | L5: Ireland | M5: Finland | N5: South Korea | O5: Singapore | AE5: Indonesia
B6: REST OF WORLD COUNTRIES | I6: Luxembourg | K6: Italy | L6: Portugal | M6: Greece | O6: Malaysia | AE6: Philipines
K7: Spain | L7: Sweden | O7: Thailand
K8: Switzerland | AI8: Zone Guide
A9: 0.5 | B9: 1186.5 | C9: 1222.2 | D9: 1249.5 | E9: 1082.55 | F9: 1120.35 | G9: 1129.8 | H9: 770.7 | I9: 825.3 | J9: 823.2 | K9: 845.25 | L9: 949.2 | M9: 964.95 | N9: 1182.3 | O9: 1062.6 | P9: 1231.65 | Q9: 1286.25 | R9: 1635.375 | S9: 1594.95 | T9: 1502.025 | U9: 913.5 | V9: 1599.15 | W9: 2459.1 | X9: 2150.4 | Y9: 2278.5 | Z9: 1484.175 | AA9: 1222.2 | AB9: 1250.025 | AC9: 1228.5 | AD9: 1661.625 | AE9: 1480.5 | AF9: 2465.4 | AG9: 2278.5 | AI9: ZONE 1 | AJ9: Bangladesh, Nepal, Sri Lanka,
A10: 0.5 | B10: 1473.15 | C10: 1515.15 | D10: 1547.7 | E10: 1088.85 | F10: 1142.4 | G10: 1151.85 | H10: 914.55 | I10: 979.65 | J10: 977.55 | K10: 1002.75 | L10: 1125.6 | M10: 1144.5 | N10: 1245.3 | O10: 1132.95 | P10: 1462.65 | Q10: 1564.5 | R10: 1864.275 | S10: 1804.95 | T10: 2201.325 | U10: 1017.45 | V10: 2179.8 | W10: 2724.75 | X10: 2713.2 | Y10: 2833.95 | Z10: 1770.825 | AA10: 1508.85 | AB10: 1536.675 | AC10: 1515.15 | AD10: 1890.525 | AE10: 2179.8 | AF10: 2731.05 | AG10: 2833.95 | AI10: ZONE 2 | AJ10: Macau, Taiwan, Vietnam,
A11: 1 | B11: 1691.55 | C11: 1751.4 | D11: 1794.45 | E11: 1455.3 | F11: 1505.7 | G11: 1518.3 | H11: 1095.15 | I11: 1171.8 | J11: 1167.6 | K11: 1199.1 | L11: 1345.05 | M11: 1367.1 | N11: 1524.6 | O11: 1434.3 | P11: 1548.75 | Q11: 1685.25 | R11: 2263.8 | S11: 2128.35 | T11: 2713.2 | U11: 1207.5 | V11: 2532.6 | W11: 3147.9 | X11: 3142.65 | Y11: 3277.05 | Z11: 2104.2 | AA11: 1741.95 | AB11: 1797.6 | AC11: 1754.55 | AD11: 2295.3 | AE11: 2649.15 | AF11: 3139.5 | AG11: 3256.05 | AI11: ZONE 3 | AJ11: Bahrain, Jordan, Kuwait, Lebanon, Oman, Pakistan, Qatar, Saudi Arabia,
A12: 1.5 | B12: 1957.2 | C12: 2037 | D12: 2090.55 | E12: 1704.15 | F12: 1761.9 | G12: 1776.6 | H12: 1305.15 | I12: 1393.35 | J12: 1389.15 | K12: 1449 | L12: 1594.95 | M12: 1620.15 | N12: 1828.05 | O12: 1713.6 | P12: 1853.25 | Q12: 2012.85 | R12: 2880.675 | S12: 2479.05 | T12: 3251.325 | U12: 1518.3 | V12: 2934.75 | W12: 3618.3 | X12: 3616.2 | Y12: 3774.75 | Z12: 2667.525 | AA12: 2043.3 | AB12: 2126.775 | AC12: 2062.2 | AD12: 2938.425 | AE12: 3165.75 | AF12: 3616.2 | AG12: 3753.75 | AI12: ZONE 4 | AJ12: Andorra, San Marino,
A13: 2 | B13: 2181.9 | C13: 2280.6 | D13: 2344.65 | E13: 1921.5 | F13: 1953 | G13: 1953 | H13: 1412.25 | I13: 1501.5 | J13: 1497.3 | K13: 1560.3 | L13: 1718.85 | M13: 1746.15 | N13: 1988.7 | O13: 1855.35 | P13: 2082.15 | Q13: 2178.75 | R13: 3164.7 | S13: 2659.65 | T13: 3586.8 | U13: 1634.85 | V13: 3123.75 | W13: 3838.8 | X13: 4047.75 | Y13: 4230.45 | Z13: 3007.2 | AA13: 2282.7 | AB13: 2394 | AC13: 2307.9 | AD13: 3227.7 | AE13: 3458.7 | AF13: 3822 | AG13: 4188.45 | AI13: ZONE 5 | AJ13: Country wise
A14: 2.5 | B14: 2448.6 | C14: 2565.15 | D14: 2639.7 | E14: 2343.6 | F14: 2381.4 | G14: 2381.4 | H14: 1621.2 | I14: 1714.65 | J14: 1724.1 | K14: 1780.8 | L14: 1958.25 | M14: 1989.75 | N14: 2278.5 | O14: 2121 | P14: 2428.65 | Q14: 2495.85 | R14: 3615.675 | S14: 3005.1 | T14: 4118.625 | U14: 1867.95 | V14: 3505.95 | W14: 4286.1 | X14: 4520.25 | Y14: 4728.15 | Z14: 3571.575 | AA14: 2585.1 | AB14: 2724.225 | AC14: 2616.6 | AD14: 3704.925 | AE14: 3969 | AF14: 4275.6 | AG14: 4686.15 | AI14: ZONE 6 | AJ14: Guernsey, Jersey, Saipan,
A15: 3 | B15: 2673.3 | C15: 2808.75 | D15: 2894.85 | E15: 2563.05 | F15: 2606.1 | G15: 2606.1 | H15: 1758.75 | I15: 1860.6 | J15: 1871.1 | K15: 2026.5 | L15: 2123.1 | M15: 2156.7 | N15: 2514.75 | O15: 2346.75 | P15: 2653.35 | Q15: 3049.2 | R15: 4189.5 | S15: 3270.75 | T15: 4534.95 | U15: 2273.25 | V15: 3847.2 | W15: 4697.7 | X15: 4949.7 | Y15: 5183.85 | Z15: 3911.25 | AA15: 2824.5 | AB15: 2991.45 | AC15: 2862.3 | AD15: 4284 | AE15: 4342.8 | AF15: 4672.5 | AG15: 5120.85 | AI15: ZONE 7 | AJ15: Algeria, Benin, Bhutan, Botswana, Brunei, Burkina Faso, Burundi, Cambodia, Central African Rep, Chad, Cook Isl, Ethiopia, ,
A16: 3.5 | B16: 2940 | C16: 3094.35 | D16: 3190.95 | E16: 2933.7 | F16: 3007.2 | G16: 3007.2 | H16: 1950.9 | I16: 2044.35 | J16: 2055.9 | K16: 2223.9 | L16: 2326.8 | M16: 2362.5 | N16: 2828.7 | O16: 2615.55 | P16: 2916.9 | Q16: 3284.4 | R16: 4605.825 | S16: 3560.55 | T16: 4994.325 | U16: 2497.95 | V16: 4229.4 | W16: 5141.85 | X16: 5423.25 | Y16: 5682.6 | Z16: 4475.625 | AA16: 3126.9 | AB16: 3321.675 | AC16: 3171 | AD16: 4726.575 | AE16: 4780.65 | AF16: 5122.95 | AG16: 5619.6 | AJ16: French Polynesia, Gabon, Ghana, Guam, Guinea Rep, Guinea-Bissau, Kenya, Kiribati, Laos, Lesotho, Liberia, Madagascar, Malawi,
A17: 4 | B17: 3163.65 | C17: 3337.95 | D17: 3444 | E17: 3228.75 | F17: 3257.1 | G17: 3284.4 | H17: 2089.5 | I17: 2190.3 | J17: 2219.7 | K17: 2380.35 | L17: 2492.7 | M17: 2531.55 | N17: 3101.7 | O17: 2840.25 | P17: 3137.4 | Q17: 3533.25 | R17: 4981.2 | S17: 3810.45 | T17: 5410.65 | U17: 2681.7 | V17: 4569.6 | W17: 5548.2 | X17: 5853.75 | Y17: 6137.25 | Z17: 4814.25 | AA17: 3365.25 | AB17: 3587.85 | AC17: 3415.65 | AD17: 5107.2 | AE17: 5154.45 | AF17: 5514.6 | AG17: 6053.25 | AJ17: Mali, Marshal Isl, Mauritania, Micronesia, Mongolia, Morocco, Mozambique, Myanmar, Namibia, Nigeria,
A18: 4.5 | B18: 3429.3 | C18: 3622.5 | D18: 3739.05 | E18: 3552.15 | F18: 3582.6 | G18: 3613.05 | H18: 2283.75 | I18: 2373 | J18: 2405.55 | K18: 2578.8 | L18: 2696.4 | M18: 2737.35 | N18: 3418.8 | O18: 3109.05 | P18: 3397.8 | Q18: 3814.65 | R18: 5398.575 | S18: 4093.95 | T18: 5860.575 | U18: 2907.45 | V18: 4950.75 | W18: 5995.5 | X18: 6326.25 | Y18: 6632.85 | Z18: 5377.575 | AA18: 3666.6 | AB18: 3917.025 | AC18: 3723.3 | AD18: 5550.825 | AE18: 5582.85 | AF18: 5968.2 | AG18: 6548.85 | AJ18: Palau, Papua New Guinea, Rwanda, Senegal, Soloman Isl, South Africa, Swaziland, Tanzania, Timor Leste, Togo, Tonga, Tunisia, Tuvalu, Uganda, Vanuatu, Wallis & Futuna Isl, Zambia, Zimbabwe
A19: 5 | B19: 3654 | C19: 3865.05 | D19: 3992.1 | E19: 3836.7 | F19: 3869.25 | G19: 3901.8 | H19: 2422.35 | I19: 2516.85 | J19: 2551.5 | K19: 2735.25 | L19: 2862.3 | M19: 2906.4 | N19: 3660.3 | O19: 3335.85 | P19: 3619.35 | Q19: 4381.65 | R19: 5776.05 | S19: 4337.55 | T19: 6283.2 | U19: 3087 | V19: 5286.75 | W19: 6400.8 | X19: 6756.75 | Y19: 7088.55 | Z19: 5717.25 | AA19: 3906 | AB19: 4184.25 | AC19: 3969 | AD19: 5933.55 | AE19: 5962.95 | AF19: 6358.8 | AG19: 6983.55
A20: 5.5 | B20: 3901.8 | C20: 4131.75 | D20: 4269.3 | E20: 4097.1 | F20: 4131.75 | G20: 4165.35 | H20: 2584.05 | I20: 2684.85 | J20: 2723.7 | K20: 2916.9 | L20: 3049.2 | M20: 3095.4 | N20: 4461.45 | O20: 3577.35 | P20: 3982.65 | Q20: 4690.35 | R20: 7148.925 | S20: 5620.65 | T20: 7452.375 | U20: 3309.6 | V20: 5633.25 | W20: 7338.45 | X20: 7178.85 | Y20: 7549.5 | Z20: 6262.725 | AA20: 4189.5 | AB20: 4495.575 | AC20: 4258.8 | AD20: 7332.675 | AE20: 7110.6 | AF20: 7302.75 | AG20: 7444.5 | AI20: ZONE 8 | AJ20: Czech Rep, Hungary, Poland,
A21: 6 | B21: 4112.85 | C21: 4361.7 | D21: 4508.7 | E21: 4322.85 | F21: 4358.55 | G21: 4395.3 | H21: 2710.05 | I21: 2815.05 | J21: 2852.85 | K21: 3055.5 | L21: 3195.15 | M21: 3243.45 | N21: 4750.2 | O21: 3916.5 | P21: 4248.3 | Q21: 4959.15 | R21: 7500.15 | S21: 5867.4 | T21: 7911.75 | U21: 3487.05 | V21: 5930.4 | W21: 7722.75 | X21: 7562.1 | Y21: 7980 | Z21: 6588.75 | AA21: 4415.25 | AB21: 4749.15 | AC21: 4490.85 | AD21: 7689.15 | AE21: 7527.45 | AF21: 7672.35 | AG21: 7854 | AI21: ZONE 9 | AJ21: Anguilla, Antigua & Barbados, Barbados, Belize, Bonaire, Brazil, Cayman Isl, Chile, Colombia, Cuba, Dominica, Dominican Rep
A22: 6.5 | B22: 4373.25 | C22: 4639.95 | D22: 4798.5 | E22: 4591.65 | F22: 4629.45 | G22: 4668.3 | H22: 2872.8 | I22: 2983.05 | J22: 3022.95 | K22: 3236.1 | L22: 3384.15 | M22: 3435.6 | N22: 5077.8 | O22: 4205.25 | P22: 4519.2 | Q22: 5269.95 | R22: 7874.475 | S22: 6155.1 | T22: 8411.025 | U22: 3712.8 | V22: 6280.05 | W22: 8140.65 | X22: 7985.25 | Y22: 8465.1 | Z22: 7146.825 | AA22: 4711.35 | AB22: 5073.075 | AC22: 4793.25 | AD22: 8089.725 | AE22: 8005.2 | AF22: 8096.55 | AG22: 8339.1 | AJ22: , Ecuador, El Salvador, Honduras, Montserrat, Nicaragua, Peru, St Kitts & Nevis, St Vincent & Grenadi
A23: 7 | B23: 4591.65 | C23: 4878.3 | D23: 5046.3 | E23: 4814.25 | F23: 4855.2 | G23: 4895.1 | H23: 2998.8 | I23: 3114.3 | J23: 3157.35 | K23: 3379.95 | L23: 3529.05 | M23: 3582.6 | N23: 5368.65 | O23: 4531.8 | P23: 4749.15 | Q23: 5536.65 | R23: 8206.8 | S23: 6406.05 | T23: 8868.3 | U23: 3891.3 | V23: 6582.45 | W23: 8517.6 | X23: 8366.4 | Y23: 8910.3 | Z23: 7480.2 | AA23: 4944.45 | AB23: 5334 | AC23: 5032.65 | AD23: 8427.3 | AE23: 8419.95 | AF23: 8458.8 | AG23: 8763.3 | AJ23: , St Martin, St Mateen, Turks & Caicos Isl, Venezuela,
A24: 7.5 | B24: 4852.05 | C24: 5156.55 | D24: 5336.1 | E24: 5083.05 | F24: 5126.1 | G24: 5168.1 | H24: 3162.6 | I24: 3283.35 | J24: 3325.35 | K24: 3557.4 | L24: 3715.95 | M24: 3771.6 | N24: 5698.35 | O24: 4799.55 | P24: 5021.1 | Q24: 5845.35 | R24: 8583.225 | S24: 6676.95 | T24: 9366.525 | U24: 4114.95 | V24: 6928.95 | W24: 8931.3 | X24: 8789.55 | Y24: 9395.4 | Z24: 8038.275 | AA24: 5240.55 | AB24: 5657.925 | AC24: 5335.05 | AD24: 8829.975 | AE24: 8896.65 | AF24: 8878.8 | AG24: 9248.4
A25: 8 | B25: 5056.8 | C25: 5380.2 | D25: 5569.2 | E25: 5309.85 | F25: 5353.95 | G25: 5398.05 | H25: 3287.55 | I25: 3412.5 | J25: 3460.8 | K25: 3702.3 | L25: 3866.1 | M25: 3923.85 | N25: 5988.15 | O25: 5030.55 | P25: 5251.05 | Q25: 6112.05 | R25: 8912.4 | S25: 6910.05 | T25: 9829.05 | U25: 4258.8 | V25: 7233.45 | W25: 9303 | X25: 9171.75 | Y25: 9812.25 | Z25: 8358 | AA25: 5460 | AB25: 5905.2 | AC25: 5560.8 | AD25: 9164.4 | AE25: 9316.65 | AF25: 9235.8 | AG25: 9644.25 | AI25: ZONE 10 | AJ25: Albania, Armenia, Belarus, Bosnia & Herzegovina, Croatia, Estonia, Georgia, Kosovo, Latvia, Lithuania,
A26: 8.5 | B26: 5297.25 | C26: 5639.55 | D26: 5838 | E26: 5574.45 | F26: 5620.65 | G26: 5666.85 | H26: 3452.4 | I26: 3582.6 | J26: 3627.75 | K26: 3879.75 | L26: 4051.95 | M26: 4111.8 | N26: 6316.8 | O26: 5306.7 | P26: 5521.95 | Q26: 6571.95 | R26: 9288.825 | S26: 7188.3 | T26: 10326.225 | U26: 4446.75 | V26: 7573.65 | W26: 9709.35 | X26: 9595.95 | Y26: 10260.6 | Z26: 8896.125 | AA26: 5736.15 | AB26: 6209.175 | AC26: 5843.25 | AD26: 9567.075 | AE26: 9792.3 | AF26: 9648.45 | AG26: 10092.6 | AJ26: Macedonia, Moldova, Montenegro, Serbia Montenegro, Slovenia, Ukraine,
A27: 9 | B27: 5490.45 | C27: 5850.6 | D27: 6059.55 | E27: 5798.1 | F27: 5846.4 | G27: 5893.65 | H27: 3576.3 | I27: 3711.75 | J27: 3760.05 | K27: 4021.5 | L27: 4202.1 | M27: 4264.05 | N27: 6606.6 | O27: 5539.8 | P27: 5751.9 | Q27: 6847.05 | R27: 9624.3 | S27: 7421.4 | T27: 10784.55 | U27: 4590.6 | V27: 7880.25 | W27: 10075.8 | X27: 9977.1 | Y27: 10655.4 | Z27: 9204.3 | AA27: 5944.05 | AB27: 6444.9 | AC27: 6057.45 | AD27: 9907.8 | AE27: 10208.1 | AF27: 10000.2 | AG27: 10466.4
A28: 9.5 | B28: 5724.6 | C28: 6102.6 | D28: 6322.05 | E28: 6054.3 | F28: 6103.65 | G28: 6154.05 | H28: 3738 | I28: 3877.65 | J28: 3933.3 | K28: 4205.25 | L28: 4382.7 | M28: 4447.8 | N28: 6935.25 | O28: 5815.95 | P28: 6015.45 | Q28: 7154.7 | R28: 9996.525 | S28: 7696.5 | T28: 11271.225 | U28: 4780.65 | V28: 8221.5 | W28: 10486.35 | X28: 10400.25 | Y28: 11090.1 | Z28: 9736.125 | AA28: 6213.9 | AB28: 6742.575 | AC28: 6333.6 | AD28: 10306.275 | AE28: 10673.25 | AF28: 10417.05 | AG28: 10901.1 | AI28: ZONE 11 | AJ28: Maldives, Mauritius, New Caledonia,
A29: 10 | B29: 5916.75 | C29: 6313.65 | D29: 6541.5 | E29: 6259.05 | F29: 6310.5 | G29: 6361.95 | H29: 3868.2 | I29: 4014.15 | J29: 4065.6 | K29: 4347 | L29: 4534.95 | M29: 4602.15 | N29: 7222.95 | O29: 6060.6 | P29: 6742.05 | Q29: 7486.5 | R29: 10348.8 | S29: 7930.65 | T29: 11716.95 | U29: 4927.65 | V29: 8527.05 | W29: 10851.75 | X29: 10782.45 | Y29: 11482.8 | Z29: 10043.25 | AA29: 6420.75 | AB29: 6977.25 | AC29: 6546.75 | AD29: 10663.8 | AE29: 11076.45 | AF29: 10767.75 | AG29: 11272.8
A30: 10.5 | B30: 6138.3 | C30: 6553.05 | D30: 6791.4 | E30: 6161.4 | F30: 6211.8 | G30: 6262.2 | H30: 4064.55 | I30: 4216.8 | J30: 4303.95 | K30: 4564.35 | L30: 4758.6 | M30: 4828.95 | N30: 7441.35 | O30: 6270.6 | P30: 7014 | Q30: 7861.35 | R30: 10778.775 | S30: 8166.9 | T30: 12181.575 | U30: 4933.95 | V30: 9871.05 | W30: 11877.6 | X30: 11104.8 | Y30: 11894.4 | Z30: 10562.475 | AA30: 6678 | AB30: 7262.325 | AC30: 6810.3 | AD30: 11120.025 | AE30: 11519.55 | AF30: 11799.9 | AG30: 11684.4 | AI30: ZONE 12 | AJ30: Argentina, Aruba, Bahamas, Bermuda, Bolivia, British Virgin Isl, Costa Rica, Curacao, Grenada, Guadeloupe
A31: 11 | B31: 6317.85 | C31: 6750.45 | D31: 6998.25 | E31: 6376.65 | F31: 6428.1 | G31: 6479.55 | H31: 4225.2 | I31: 4383.75 | J31: 4474.05 | K31: 4746 | L31: 4952.85 | M31: 5026.35 | N31: 7614.6 | O31: 6439.65 | P31: 7238.7 | Q31: 8107.05 | R31: 11174.1 | S31: 8347.5 | T31: 12606.3 | U31: 5082 | V31: 10129.35 | W31: 12266.1 | X31: 11389.35 | Y31: 12262.95 | Z31: 10857 | AA31: 6872.25 | AB31: 7484.4 | AC31: 7010.85 | AD31: 11520.6 | AE31: 11901.75 | AF31: 12173.7 | AG31: 12031.95 | AJ31: Guatemala, Guyana, Haiti, Jamaica, Martinique, Panama, Paraguay, St Barthelemy, St Lucia, Suriname, Trinidad & Tobago, US Virgin Isl, Uruguay,
A32: 11.5 | B32: 6538.35 | C32: 6989.85 | D32: 7247.1 | E32: 6632.85 | F32: 6687.45 | G32: 6741 | H32: 4414.2 | I32: 4579.05 | J32: 4677.75 | K32: 4961.25 | L32: 5177.55 | M32: 5254.2 | N32: 7831.95 | O32: 6652.8 | P32: 7506.45 | Q32: 8394.75 | R32: 11549.475 | S32: 8570.1 | T32: 13066.725 | U32: 5275.2 | V32: 10421.25 | W32: 12696.6 | X32: 11713.8 | Y32: 12672.45 | Z32: 11375.175 | AA32: 7128.45 | AB32: 7768.425 | AC32: 7273.35 | AD32: 11922.225 | AE32: 12340.65 | AF32: 12610.5 | AG32: 12441.45
A33: 12 | B33: 6718.95 | C33: 7187.25 | D33: 7455 | E33: 6842.85 | F33: 6898.5 | G33: 6954.15 | H33: 4575.9 | I33: 4748.1 | J33: 4847.85 | K33: 5142.9 | L33: 5366.55 | M33: 5446.35 | N33: 8008.35 | O33: 6828.15 | P33: 7732.2 | Q33: 8638.35 | R33: 11880.75 | S33: 8754.9 | T33: 13488.3 | U33: 5434.8 | V33: 10675.35 | W33: 13080.9 | X33: 11997.3 | Y33: 13042.05 | Z33: 11670.75 | AA33: 7323.75 | AB33: 7991.55 | AC33: 7474.95 | AD33: 12258.75 | AE33: 12719.7 | AF33: 12980.1 | AG33: 12790.05 | AI33: ZONE 13 | AJ33: Bulgaria, Cyprus, Gibraltar, Iceland, Malta, Romania, Slovakia, Turkey,
A34: 12.5 | B34: 6940.5 | C34: 7426.65 | D34: 7703.85 | E34: 7102.2 | F34: 7159.95 | G34: 7216.65 | H34: 4773.3 | I34: 4951.8 | J34: 5053.65 | K34: 5360.25 | L34: 5595.45 | M34: 5678.4 | N34: 8226.75 | O34: 7042.35 | P34: 8001 | Q34: 8977.5 | R34: 12227.775 | S34: 8976.45 | T34: 13951.875 | U34: 5619.6 | V34: 10980.9 | W34: 13511.4 | X34: 12322.8 | Y34: 13452.6 | Z34: 12189.975 | AA34: 7581 | AB34: 8276.625 | AC34: 7738.5 | AD34: 12632.025 | AE34: 13161.75 | AF34: 13416.9 | AG34: 13200.6 | AI34: ZONE 14 | AJ34: Angola, Azerbaijan, Cape Verde, Comoros, Equatorial Guinea, Eritrea, Faroe Isl, Greenland, Kazakhstan, Kyrgyzstan, Mayotte, Tajikistan, Uzbekistan,
A35: 13 | B35: 7119 | C35: 7624.05 | D35: 7910.7 | E35: 7299.6 | F35: 7358.4 | G35: 7418.25 | H35: 4933.95 | I35: 5118.75 | J35: 5219.55 | K35: 5536.65 | L35: 5782.35 | M35: 5867.4 | N35: 8402.1 | O35: 7220.85 | P35: 8218.35 | Q35: 9222.15 | R35: 12529.65 | S35: 9160.2 | T35: 14364 | U35: 5776.05 | V35: 11291.7 | W35: 13902 | X35: 12666.15 | Y35: 13820.1 | Z35: 12483.45 | AA35: 7774.2 | AB35: 8497.65 | AC35: 7938 | AD35: 12939.15 | AE35: 13531.35 | AF35: 13792.8 | AG35: 13547.1 | AI35: ZONE 15 | AJ35: American Samoa, Cameroon, Congo, Djibouti, Gambia, Ivory Coast, Niger, Reunion Isl, Seychelles, Sierra Leone, Samoa,
A36: 13.5 | B36: 7340.55 | C36: 7863.45 | D36: 8159.55 | E36: 7539 | F36: 7599.9 | G36: 7660.8 | H36: 5128.2 | I36: 5319.3 | J36: 5429.55 | K36: 5758.2 | L36: 6007.05 | M36: 6096.3 | N36: 8619.45 | O36: 7443.45 | P36: 8479.8 | Q36: 9509.85 | R36: 12872.475 | S36: 9381.75 | T36: 14814.975 | U36: 5973.45 | V36: 11637.15 | W36: 14334.6 | X36: 13052.55 | Y36: 14230.65 | Z36: 13002.675 | AA36: 8031.45 | AB36: 8782.725 | AC36: 8201.55 | AD36: 13308.225 | AE36: 13960.8 | AF36: 14231.7 | AG36: 13957.65 | AJ36: St Croix, St Eustatius, St John, St Kitts & Nevis, St Martin, St Marteen, St Thomas, St Vincent & Grenadi, Tahiti, Tortola, Truk,
A37: 14 | B37: 7520.1 | C37: 8060.85 | D37: 8367.45 | E37: 7738.5 | F37: 7801.5 | G37: 7863.45 | H37: 5285.7 | I37: 5484.15 | J37: 5599.65 | K37: 5938.8 | L37: 6198.15 | M37: 6289.5 | N37: 8793.75 | O37: 7624.05 | P37: 8705.55 | Q37: 9758.7 | R37: 13180.65 | S37: 9558.15 | T37: 15235.5 | U37: 6122.55 | V37: 11942.7 | W37: 14721 | X37: 13398 | Y37: 14599.2 | Z37: 13297.2 | AA37: 8225.7 | AB37: 9004.8 | AC37: 8402.1 | AD37: 13621.65 | AE37: 14338.8 | AF37: 14603.4 | AG37: 14305.2 | AJ37: Turks & Caicas Island, Venezuela, Yap, Zaire
A38: 14.5 | B38: 7740.6 | C38: 8300.25 | D38: 8616.3 | E38: 7978.95 | F38: 8043 | G38: 8108.1 | H38: 5479.95 | I38: 5684.7 | J38: 5804.4 | K38: 6155.1 | L38: 6420.75 | M38: 6515.25 | N38: 9012.15 | O38: 7847.7 | P38: 8967 | Q38: 10154.55 | R38: 13522.425 | S38: 9773.4 | T38: 15692.775 | U38: 6316.8 | V38: 12308.1 | W38: 15149.4 | X38: 13785.45 | Y38: 15008.7 | Z38: 13815.375 | AA38: 8481.9 | AB38: 9288.825 | AC38: 8664.6 | AD38: 13989.675 | AE38: 14774.55 | AF38: 15038.1 | AG38: 14714.7
A39: 15 | B39: 7921.2 | C39: 8498.7 | D39: 8824.2 | E39: 8185.8 | F39: 8251.95 | G39: 8318.1 | H39: 5637.45 | I39: 5848.5 | J39: 5968.2 | K39: 6329.4 | L39: 6609.75 | M39: 6707.4 | N39: 9189.6 | O39: 8033.55 | P39: 9183.3 | Q39: 10438.05 | R39: 13825.35 | S39: 9951.9 | T39: 16101.75 | U39: 6468 | V39: 12618.9 | W39: 15537.9 | X39: 14127.75 | Y39: 15379.35 | Z39: 14110.95 | AA39: 8677.2 | AB39: 9511.95 | AC39: 8866.2 | AD39: 14297.85 | AE39: 15141 | AF39: 15411.9 | AG39: 15064.35
A40: 15.5 | B40: 8141.7 | C40: 8737.05 | D40: 9072 | E40: 9168.6 | F40: 9243.15 | G40: 9317.7 | H40: 6222.3 | I40: 6609.75 | J40: 6638.1 | K40: 6844.95 | L40: 7308 | M40: 7587.3 | N40: 10327.8 | O40: 9047.85 | P40: 10426.5 | Q40: 11844 | R40: 15239.175 | S40: 11172 | T40: 17903.025 | U40: 7262.85 | V40: 14270.55 | W40: 17569.65 | X40: 14514.15 | Y40: 15787.8 | Z40: 14629.125 | AA40: 8933.4 | AB40: 9795.975 | AC40: 9128.7 | AD40: 15737.925 | AE40: 16920.75 | AF40: 17449.95 | AG40: 15472.8
A41: 16 | B41: 8321.25 | C41: 8934.45 | D41: 9279.9 | E41: 9361.8 | F41: 9438.45 | G41: 9515.1 | H41: 6388.2 | I41: 6787.2 | J41: 6822.9 | K41: 7036.05 | L41: 7515.9 | M41: 7804.65 | N41: 10522.05 | O41: 9191.7 | P41: 10679.55 | Q41: 12217.8 | R41: 15563.1 | S41: 11366.25 | T41: 18355.05 | U41: 7417.2 | V41: 14611.8 | W41: 18004.35 | X41: 14858.55 | Y41: 16156.35 | Z41: 14923.65 | AA41: 9127.65 | AB41: 10018.05 | AC41: 9329.25 | AD41: 16067.1 | AE41: 17330.25 | AF41: 17869.95 | AG41: 15820.35
A42: 16.5 | B42: 8543.85 | C42: 9174.9 | D42: 9529.8 | E42: 9604.35 | F42: 9682.05 | G42: 9760.8 | H42: 6595.05 | I42: 7004.55 | J42: 7039.2 | K42: 7258.65 | L42: 7751.1 | M42: 8048.25 | N42: 10759.35 | O42: 9310.35 | P42: 10962 | Q42: 12575.85 | R42: 15927.975 | S42: 11604.6 | T42: 18839.625 | U42: 7613.55 | V42: 15006.6 | W42: 18471.6 | X42: 15244.95 | Y42: 16569 | Z42: 15443.925 | AA42: 9385.95 | AB42: 10304.175 | AC42: 9593.85 | AD42: 16458.225 | AE42: 17793.3 | AF42: 18343.5 | AG42: 16233
...
